<?xml version="1.0"?>
<robot xmlns:xacro="http://www.ros.org/wiki/xacro">
    <xacro:macro name="link_wheel" params="name">
        <link name="${name}">
            <inertial>
              <mass value="0.2"/>
              <origin rpy="0 1.5707 1.5707" xyz="0 0 0"/>
              <inertia ixx="0.000526666666667" ixy="0" ixz="0" iyy="0.000526666666667" iyz="0" izz="0.001"/>
            </inertial>
            <collision name="link_right_wheel_collision">
              <origin rpy="0 1.5707 1.5707" xyz="0.0 0 0"/>
              <geometry>
                <cylinder length="0.04" radius="0.05"/>
              </geometry>
            </collision>
            <visual name="${name}_visual">
              <origin rpy="0 1.5707 1.5707" xyz="0.0 0 0"/>
              <geometry>
                <cylinder length="0.05" radius="0.05"/>
              </geometry>
            </visual>
        </link>
    </xacro:macro>

       <xacro:macro name="link_dummy" params="name">
        <link name="${name}">
            <inertial>
              <mass value="0.2"/>
              <origin rpy="0 0 0" xyz="0 0 0"/>
              <inertia ixx="0.000526666666667" ixy="0" ixz="0" iyy="0.000526666666667" iyz="0" izz="0.001"/>
            </inertial>
            <collision name="link_right_wheel_collision">
              <origin rpy="0 0 1.5707" xyz="0.0 0 0"/>
              <geometry>
                <mesh filename="package://pmr/meshes/xbox.dae" scale="0.01 0.01 0.01"/>
              </geometry>
            </collision>
            <visual name="${name}_visual">
              <origin rpy="0 0 1.5707" xyz="0.0 0 0"/>
              <geometry>
                <mesh filename="package://pmr/meshes/xbox.dae" scale="0.1 0.1 0.1"/>
              </geometry>
            </visual>
        </link>
    </xacro:macro>

    <xacro:macro name="joint_wheel" params="name child origin_xyz axis_xyz origin_rpy">
      <joint name="${name}" type="continuous">
        <origin rpy="${origin_rpy}" xyz="${origin_xyz}"/>
        <child link="${child}"/>
        <parent link="link_chassis"/>
        <axis rpy="0 0 0" xyz="${axis_xyz}"/>
        <limit effort="10000" velocity="10"/>
        <joint_properties damping="1.0" friction="0.6"/>
      </joint>
    </xacro:macro>

</robot>